/cm/shared/apps/python/3.5.2/lib/python3.5/site-packages/h5py/__init__.py:34: FutureWarning: Conversion of the second argument of issubdtype from `float` to `np.floating` is deprecated. In future, it will be treated as `np.float64 == np.dtype(float).type`.
  from ._conv import register_converters as _register_converters
parameters: {'test_batch_size': 128, 'test_interval': 1000, 'gpu': True, 'lr_halve_interval': 15000.0, 'chunk_size': 2048, 'maxlen': 1024, 'seed': 1337, 'class_weights': None, 'shuffle': True, 'model_save_path': 'models/VDCNN/VDCNN_ag_news---lex1_depth@9/25', 'model_folder': 'models/VDCNN/VDCNN_ag_news---lex1_depth@9/25', 'combined_datasets': 'ag_news---lex1', 'batch_size': 128, 'joint_test': 0, 'model_load_path': 'models/VDCNN/VDCNN_ag_news---lex1_depth@9/25/best_model.pt', 'joint_training': True, 'num_embedding_features': 100, 'num_prev_classes': 20, 'dataset': 'ng20', 'test_only': 0, 'iterations': 50000, 'test_dataset': 'ag_news', 'depth': 9, 'lr': 0.01, 'shortcut': False, 'transfer_weights': False, 'freeze_pre_trained_layers': False, 'transfer_lr': 0.001, 'last_pooling_layer': 'k-max-pooling', 'joint_ratio': 0.25}
Joint Training !
dataset: AgNews, n_classes: 4
  - loading dataset...
dataset: Lex1, n_classes: 38
  - loading dataset...
Both datasets loaded, going to mix ...
  - txt vectorization...
--- Logging error ---
Traceback (most recent call last):
  File "/cm/shared/apps/python/3.5.2/lib/python3.5/logging/__init__.py", line 980, in emit
    msg = self.format(record)
  File "/cm/shared/apps/python/3.5.2/lib/python3.5/logging/__init__.py", line 830, in format
    return fmt.format(record)
  File "/cm/shared/apps/python/3.5.2/lib/python3.5/logging/__init__.py", line 567, in format
    record.message = record.getMessage()
  File "/cm/shared/apps/python/3.5.2/lib/python3.5/logging/__init__.py", line 330, in getMessage
    msg = msg % self.args
TypeError: not all arguments converted during string formatting
Call stack:
  File "/cm/shared/apps/python/3.5.2/lib/python3.5/runpy.py", line 184, in _run_module_as_main
    "__main__", mod_spec)
  File "/cm/shared/apps/python/3.5.2/lib/python3.5/runpy.py", line 85, in _run_code
    exec(code, run_globals)
  File "/home/usaxena/work/s18/lex/code/vdcnn/src/VDCNN.py", line 453, in <module>
    joint_train(opt, logger)
  File "/home/usaxena/work/s18/lex/code/vdcnn/src/VDCNN.py", line 338, in joint_train
    logger.info("Number of classes in the mixed dataset are: ", n_classes, type(n_classes))
Message: 'Number of classes in the mixed dataset are: '
Arguments: (14, <class 'int'>)
--- Logging error ---
Traceback (most recent call last):
  File "/cm/shared/apps/python/3.5.2/lib/python3.5/logging/__init__.py", line 980, in emit
    msg = self.format(record)
  File "/cm/shared/apps/python/3.5.2/lib/python3.5/logging/__init__.py", line 830, in format
    return fmt.format(record)
  File "/cm/shared/apps/python/3.5.2/lib/python3.5/logging/__init__.py", line 567, in format
    record.message = record.getMessage()
  File "/cm/shared/apps/python/3.5.2/lib/python3.5/logging/__init__.py", line 330, in getMessage
    msg = msg % self.args
TypeError: not all arguments converted during string formatting
Call stack:
  File "/cm/shared/apps/python/3.5.2/lib/python3.5/runpy.py", line 184, in _run_module_as_main
    "__main__", mod_spec)
  File "/cm/shared/apps/python/3.5.2/lib/python3.5/runpy.py", line 85, in _run_code
    exec(code, run_globals)
  File "/home/usaxena/work/s18/lex/code/vdcnn/src/VDCNN.py", line 453, in <module>
    joint_train(opt, logger)
  File "/home/usaxena/work/s18/lex/code/vdcnn/src/VDCNN.py", line 338, in joint_train
    logger.info("Number of classes in the mixed dataset are: ", n_classes, type(n_classes))
Message: 'Number of classes in the mixed dataset are: '
Arguments: (14, <class 'int'>)
--- Logging error ---
Traceback (most recent call last):
  File "/cm/shared/apps/python/3.5.2/lib/python3.5/logging/__init__.py", line 980, in emit
    msg = self.format(record)
  File "/cm/shared/apps/python/3.5.2/lib/python3.5/logging/__init__.py", line 830, in format
    return fmt.format(record)
  File "/cm/shared/apps/python/3.5.2/lib/python3.5/logging/__init__.py", line 567, in format
    record.message = record.getMessage()
  File "/cm/shared/apps/python/3.5.2/lib/python3.5/logging/__init__.py", line 330, in getMessage
    msg = msg % self.args
TypeError: not all arguments converted during string formatting
Call stack:
  File "/cm/shared/apps/python/3.5.2/lib/python3.5/runpy.py", line 184, in _run_module_as_main
    "__main__", mod_spec)
  File "/cm/shared/apps/python/3.5.2/lib/python3.5/runpy.py", line 85, in _run_code
    exec(code, run_globals)
  File "/home/usaxena/work/s18/lex/code/vdcnn/src/VDCNN.py", line 453, in <module>
    joint_train(opt, logger)
  File "/home/usaxena/work/s18/lex/code/vdcnn/src/VDCNN.py", line 341, in joint_train
    logger.info("Seed for random numbers: ", torch.initial_seed())
Message: 'Seed for random numbers: '
Arguments: (1337,)
--- Logging error ---
Traceback (most recent call last):
  File "/cm/shared/apps/python/3.5.2/lib/python3.5/logging/__init__.py", line 980, in emit
    msg = self.format(record)
  File "/cm/shared/apps/python/3.5.2/lib/python3.5/logging/__init__.py", line 830, in format
    return fmt.format(record)
  File "/cm/shared/apps/python/3.5.2/lib/python3.5/logging/__init__.py", line 567, in format
    record.message = record.getMessage()
  File "/cm/shared/apps/python/3.5.2/lib/python3.5/logging/__init__.py", line 330, in getMessage
    msg = msg % self.args
TypeError: not all arguments converted during string formatting
Call stack:
  File "/cm/shared/apps/python/3.5.2/lib/python3.5/runpy.py", line 184, in _run_module_as_main
    "__main__", mod_spec)
  File "/cm/shared/apps/python/3.5.2/lib/python3.5/runpy.py", line 85, in _run_code
    exec(code, run_globals)
  File "/home/usaxena/work/s18/lex/code/vdcnn/src/VDCNN.py", line 453, in <module>
    joint_train(opt, logger)
  File "/home/usaxena/work/s18/lex/code/vdcnn/src/VDCNN.py", line 341, in joint_train
    logger.info("Seed for random numbers: ", torch.initial_seed())
Message: 'Seed for random numbers: '
Arguments: (1337,)
--- Logging error ---
Traceback (most recent call last):
  File "/cm/shared/apps/python/3.5.2/lib/python3.5/logging/__init__.py", line 980, in emit
    msg = self.format(record)
  File "/cm/shared/apps/python/3.5.2/lib/python3.5/logging/__init__.py", line 830, in format
    return fmt.format(record)
  File "/cm/shared/apps/python/3.5.2/lib/python3.5/logging/__init__.py", line 567, in format
    record.message = record.getMessage()
  File "/cm/shared/apps/python/3.5.2/lib/python3.5/logging/__init__.py", line 330, in getMessage
    msg = msg % self.args
TypeError: not all arguments converted during string formatting
Call stack:
  File "/cm/shared/apps/python/3.5.2/lib/python3.5/runpy.py", line 184, in _run_module_as_main
    "__main__", mod_spec)
  File "/cm/shared/apps/python/3.5.2/lib/python3.5/runpy.py", line 85, in _run_code
    exec(code, run_globals)
  File "/home/usaxena/work/s18/lex/code/vdcnn/src/VDCNN.py", line 453, in <module>
    joint_train(opt, logger)
  File "/home/usaxena/work/s18/lex/code/vdcnn/src/VDCNN.py", line 344, in joint_train
    logger.info("Overriding the number of embedding features to: ", n_txt_feats)
Message: 'Overriding the number of embedding features to: '
Arguments: (100,)
--- Logging error ---
Traceback (most recent call last):
  File "/cm/shared/apps/python/3.5.2/lib/python3.5/logging/__init__.py", line 980, in emit
    msg = self.format(record)
  File "/cm/shared/apps/python/3.5.2/lib/python3.5/logging/__init__.py", line 830, in format
    return fmt.format(record)
  File "/cm/shared/apps/python/3.5.2/lib/python3.5/logging/__init__.py", line 567, in format
    record.message = record.getMessage()
  File "/cm/shared/apps/python/3.5.2/lib/python3.5/logging/__init__.py", line 330, in getMessage
    msg = msg % self.args
TypeError: not all arguments converted during string formatting
Call stack:
  File "/cm/shared/apps/python/3.5.2/lib/python3.5/runpy.py", line 184, in _run_module_as_main
    "__main__", mod_spec)
  File "/cm/shared/apps/python/3.5.2/lib/python3.5/runpy.py", line 85, in _run_code
    exec(code, run_globals)
  File "/home/usaxena/work/s18/lex/code/vdcnn/src/VDCNN.py", line 453, in <module>
    joint_train(opt, logger)
  File "/home/usaxena/work/s18/lex/code/vdcnn/src/VDCNN.py", line 344, in joint_train
    logger.info("Overriding the number of embedding features to: ", n_txt_feats)
Message: 'Overriding the number of embedding features to: '
Arguments: (100,)
Joint training
Setting the lr to : 0.01
Mixed_ag_news---lex1_0.25 - Iter [0/50000] - train metrics: {'accuracy': 0.0, 'logloss': -1}
THCudaCheck FAIL file=/pytorch/torch/lib/THC/generic/THCTensorCopy.c line=21 error=59 : device-side assert triggered
/home/usaxena/work/s18/lex/code/vdcnn/src/VDCNN.py:86: UserWarning: Implicit dimension choice for softmax has been deprecated. Change the call to include dim=X as an argument.
  yhat = nn.functional.softmax(yhat)
Traceback (most recent call last):
  File "/cm/shared/apps/python/3.5.2/lib/python3.5/runpy.py", line 184, in _run_module_as_main
    "__main__", mod_spec)
  File "/cm/shared/apps/python/3.5.2/lib/python3.5/runpy.py", line 85, in _run_code
    exec(code, run_globals)
  File "/home/usaxena/work/s18/lex/code/vdcnn/src/VDCNN.py", line 453, in <module>
    joint_train(opt, logger)
  File "/home/usaxena/work/s18/lex/code/vdcnn/src/VDCNN.py", line 368, in joint_train
    train(opt, model, criterion, tr_data, te_data, n_classes, dataset_name)
  File "/home/usaxena/work/s18/lex/code/vdcnn/src/VDCNN.py", line 263, in train
    y_prob = predict_from_model(te_gen, model, gpu=opt.gpu)
  File "/home/usaxena/work/s18/lex/code/vdcnn/src/VDCNN.py", line 81, in predict_from_model
    tdata = [x.cuda() for x in tdata]
  File "/home/usaxena/work/s18/lex/code/vdcnn/src/VDCNN.py", line 81, in <listcomp>
    tdata = [x.cuda() for x in tdata]
  File "/home/usaxena/.local/lib/python3.5/site-packages/torch/autograd/variable.py", line 298, in cuda
    return CudaTransfer.apply(self, device, async)
  File "/home/usaxena/.local/lib/python3.5/site-packages/torch/autograd/_functions/tensor.py", line 201, in forward
    return i.cuda(async=async)
  File "/home/usaxena/.local/lib/python3.5/site-packages/torch/_utils.py", line 69, in _cuda
    return new_type(self.size()).copy_(self, async)
RuntimeError: cuda runtime error (59) : device-side assert triggered at /pytorch/torch/lib/THC/generic/THCTensorCopy.c:21
